<?xml version='1.0' encoding='utf-8'?>
<robot name="so101">

  <!-- Materials -->
  <material name="3d_printed">
    <color rgba="0.06 0.4 0.1 1.0"/>
  </material>
  <material name="sts3215">
    <color rgba="0.1 0.1 0.1 1.0"/>
  </material>

  <!-- Base Link -->
  <link name="Base">
    <inertial>
      <origin xyz="0 0 0" rpy="0 0 0"/>
      <mass value="0.147"/>
      <inertia ixx="0.000136117" ixy="4.59787e-07" ixz="9.75275e-08" iyy="0.000114686" iyz="-4.97151e-06" izz="0.000130364"/>
    </inertial>
    <!-- Part base_motor_holder_so101_v1 -->
    <visual>
      <origin xyz="0.0206915 0.0221255 0.0300817" rpy="1.5708 -1.23909e-16 2.33147e-15"/>
      <geometry>
        <mesh filename="meshes/base_motor_holder_so101_v1.stl"/>
      </geometry>
      <material name="3d_printed"/>
    </visual>
    <collision>
      <origin xyz="0.0206915 0.0221255 0.0300817" rpy="1.5708 -1.23909e-16 2.33147e-15"/>
      <geometry>
        <mesh filename="meshes/base_motor_holder_so101_v1.stl"/>
      </geometry>
    </collision>
    <!-- Part base_so101_v2 -->
    <visual>
      <origin xyz="0.0207909 0.0221255 0.0300817" rpy="1.5708 -0 0"/>
      <geometry>
        <mesh filename="meshes/base_so101_v2.stl"/>
      </geometry>
      <material name="3d_printed"/>
    </visual>
    <collision>
      <origin xyz="0.0207909 0.0221255 0.0300817" rpy="1.5708 -0 0"/>
      <geometry>
        <mesh filename="meshes/base_so101_v2.stl"/>
      </geometry>
    </collision>
    <!-- Part sts3215_03a_v1 -->
    <visual>
      <origin xyz="0.0207909 -0.0105745 0.0761817" rpy="-2.20282e-15 2.77556e-17 -1.5708"/>
      <geometry>
        <mesh filename="meshes/sts3215_03a_v1.stl"/>
      </geometry>
      <material name="sts3215"/>
    </visual>
    <collision>
      <origin xyz="0.0207909 -0.0105745 0.0761817" rpy="-2.20282e-15 2.77556e-17 -1.5708"/>
      <geometry>
        <mesh filename="meshes/sts3215_03a_v1.stl"/>
      </geometry>
    </collision>
    <!-- Part waveshare_mounting_plate_so101_v2 -->
    <visual>
      <origin xyz="0.0205915 0.0467435 0.0798817" rpy="1.5708 -1.21716e-14 2.33147e-15"/>
      <geometry>
        <mesh filename="meshes/waveshare_mounting_plate_so101_v2.stl"/>
      </geometry>
      <material name="3d_printed"/>
    </visual>
    <collision>
      <origin xyz="0.0205915 0.0467435 0.0798817" rpy="1.5708 -1.21716e-14 2.33147e-15"/>
      <geometry>
        <mesh filename="meshes/waveshare_mounting_plate_so101_v2.stl"/>
      </geometry>
    </collision>
  </link>

  <!-- Rotation_Pitch Link -->
  <link name="Rotation_Pitch">
    <inertial>
      <origin xyz="-0.0307604 -1.66727e-05 -0.0252713" rpy="0 0 0"/>
      <mass value="0.100006"/>
      <inertia ixx="8.3759e-05" ixy="7.55525e-08" ixz="-1.16342e-06" iyy="8.10403e-05" iyz="1.54663e-07" izz="2.39783e-05"/>
    </inertial>
    <!-- Part sts3215_03a_v1_2 -->
    <visual>
      <origin xyz="-0.0303992 0.000422241 -0.0417" rpy="1.5708 1.5708 0"/>
      <geometry>
        <mesh filename="meshes/sts3215_03a_v1.stl"/>
      </geometry>
      <material name="sts3215"/>
    </visual>
    <collision>
      <origin xyz="-0.0303992 0.000422241 -0.0417" rpy="1.5708 1.5708 0"/>
      <geometry>
        <mesh filename="meshes/sts3215_03a_v1.stl"/>
      </geometry>
    </collision>
    <!-- Part motor_holder_so101_base_v1 -->
    <visual>
      <origin xyz="-0.0675992 -0.000177759 0.0158499" rpy="1.5708 -1.5708 0"/>
      <geometry>
        <mesh filename="meshes/motor_holder_so101_base_v1.stl"/>
      </geometry>
      <material name="3d_printed"/>
    </visual>
    <collision>
      <origin xyz="-0.0675992 -0.000177759 0.0158499" rpy="1.5708 -1.5708 0"/>
      <geometry>
        <mesh filename="meshes/motor_holder_so101_base_v1.stl"/>
      </geometry>
    </collision>
    <!-- Part rotation_pitch_so101_v1 -->
    <visual>
      <origin xyz="0.0122008 2.22413e-05 0.0464" rpy="-1.5708 -0 0"/>
      <geometry>
        <mesh filename="meshes/rotation_pitch_so101_v1.stl"/>
      </geometry>
      <material name="3d_printed"/>
    </visual>
    <collision>
      <origin xyz="0.0122008 2.22413e-05 0.0464" rpy="-1.5708 -0 0"/>
      <geometry>
        <mesh filename="meshes/rotation_pitch_so101_v1.stl"/>
      </geometry>
    </collision>
  </link>

  <!-- Upper_Arm Link -->
  <link name="Upper_Arm">
    <inertial>
      <origin xyz="-0.0898471 -0.00838224 0.0184089" rpy="0 0 0"/>
      <mass value="0.103"/>
      <inertia ixx="4.08002e-05" ixy="-1.97819e-05" ixz="-4.03016e-08" iyy="0.000147318" iyz="8.97326e-09" izz="0.000142487"/>
    </inertial>
    <!-- Part sts3215_03a_v1_3 -->
    <visual>
      <origin xyz="-0.11257 -0.0155 0.0187" rpy="-3.14159 -1.31839e-15 -1.5708"/>
      <geometry>
        <mesh filename="meshes/sts3215_03a_v1.stl"/>
      </geometry>
      <material name="sts3215"/>
    </visual>
    <collision>
      <origin xyz="-0.11257 -0.0155 0.0187" rpy="-3.14159 -1.31839e-15 -1.5708"/>
      <geometry>
        <mesh filename="meshes/sts3215_03a_v1.stl"/>
      </geometry>
    </collision>
    <!-- Part upper_arm_so101_v1 -->
    <visual>
      <origin xyz="-0.065085 0.012 0.0182" rpy="-3.14159 -0 0"/>
      <geometry>
        <mesh filename="meshes/upper_arm_so101_v1.stl"/>
      </geometry>
      <material name="3d_printed"/>
    </visual>
    <collision>
      <origin xyz="-0.065085 0.012 0.0182" rpy="-3.14159 -0 0"/>
      <geometry>
        <mesh filename="meshes/upper_arm_so101_v1.stl"/>
      </geometry>
    </collision>
  </link>

  <!-- Lower_Arm Link -->
  <link name="Lower_Arm">
    <inertial>
      <origin xyz="-0.0980701 0.00324376 0.0182831" rpy="0 0 0"/>
      <mass value="0.104"/>
      <inertia ixx="2.87438e-05" ixy="7.41152e-06" ixz="1.26409e-06" iyy="0.000159844" iyz="-4.90188e-08" izz="0.00014529"/>
    </inertial>
    <!-- Part under_arm_so101_v1 -->
    <visual>
      <origin xyz="-0.0648499 -0.032 0.0182" rpy="3.14159 9.86076e-32 7.88861e-31"/>
      <geometry>
        <mesh filename="meshes/under_arm_so101_v1.stl"/>
      </geometry>
      <material name="3d_printed"/>
    </visual>
    <collision>
      <origin xyz="-0.0648499 -0.032 0.0182" rpy="3.14159 9.86076e-32 7.88861e-31"/>
      <geometry>
        <mesh filename="meshes/under_arm_so101_v1.stl"/>
      </geometry>
    </collision>
    <!-- Part motor_holder_so101_wrist_v1 -->
    <visual>
      <origin xyz="-0.0648499 -0.032 0.018" rpy="3.14159 1.58207e-15 7.14706e-16"/>
      <geometry>
        <mesh filename="meshes/motor_holder_so101_wrist_v1.stl"/>
      </geometry>
      <material name="3d_printed"/>
    </visual>
    <collision>
      <origin xyz="-0.0648499 -0.032 0.018" rpy="3.14159 1.58207e-15 7.14706e-16"/>
      <geometry>
        <mesh filename="meshes/motor_holder_so101_wrist_v1.stl"/>
      </geometry>
    </collision>
    <!-- Part sts3215_03a_v1_4 -->
    <visual>
      <origin xyz="-0.1224 0.0052 0.0187" rpy="-3.14159 -6.93889e-15 -3.14159"/>
      <geometry>
        <mesh filename="meshes/sts3215_03a_v1.stl"/>
      </geometry>
      <material name="sts3215"/>
    </visual>
    <collision>
      <origin xyz="-0.1224 0.0052 0.0187" rpy="-3.14159 -6.93889e-15 -3.14159"/>
      <geometry>
        <mesh filename="meshes/sts3215_03a_v1.stl"/>
      </geometry>
    </collision>
  </link>

  <!-- Wrist_Pitch_Roll Link -->
  <link name="Wrist_Pitch_Roll">
    <inertial>
      <origin xyz="-0.000103312 -0.0386143 0.0281156" rpy="0 0 0"/>
      <mass value="0.079"/>
      <inertia ixx="3.68263e-05" ixy="1.7893e-08" ixz="-5.28128e-08" iyy="2.5391e-05" iyz="3.6412e-06" izz="2.1e-05"/>
    </inertial>
    <!-- Part sts3215_03a_no_horn_v1 -->
    <visual>
      <origin xyz="0 -0.0424 0.0306" rpy="1.5708 1.5708 0"/>
      <geometry>
        <mesh filename="meshes/sts3215_03a_no_horn_v1.stl"/>
      </geometry>
      <material name="sts3215"/>
    </visual>
    <collision>
      <origin xyz="0 -0.0424 0.0306" rpy="1.5708 1.5708 0"/>
      <geometry>
        <mesh filename="meshes/sts3215_03a_no_horn_v1.stl"/>
      </geometry>
    </collision>
    <!-- Part wrist_roll_pitch_so101_v2 -->
    <visual>
      <origin xyz="0 -0.028 0.0181" rpy="-1.5708 -1.5708 0"/>
      <geometry>
        <mesh filename="meshes/wrist_roll_pitch_so101_v2.stl"/>
      </geometry>
      <material name="3d_printed"/>
    </visual>
    <collision>
      <origin xyz="0 -0.028 0.0181" rpy="-1.5708 -1.5708 0"/>
      <geometry>
        <mesh filename="meshes/wrist_roll_pitch_so101_v2.stl"/>
      </geometry>
    </collision>
  </link>

  <!-- Fixed_Jaw Link -->
  <link name="Fixed_Jaw">
    <inertial>
      <origin xyz="0.000213627 0.000245138 -0.025187" rpy="0 0 0"/>
      <mass value="0.087"/>
      <inertia ixx="2.75087e-05" ixy="-3.35241e-07" ixz="-5.7352e-06" iyy="4.33657e-05" iyz="-5.17847e-08" izz="3.45059e-05"/>
    </inertial>
    <!-- Part sts3215_03a_v1_5 -->
    <visual>
      <origin xyz="0.0077 0.0001 -0.0234" rpy="-1.5708 -5.55112e-17 -1.38213e-14"/>
      <geometry>
        <mesh filename="meshes/sts3215_03a_v1.stl"/>
      </geometry>
      <material name="sts3215"/>
    </visual>
    <collision>
      <origin xyz="0.0077 0.0001 -0.0234" rpy="-1.5708 -5.55112e-17 -1.38213e-14"/>
      <geometry>
        <mesh filename="meshes/sts3215_03a_v1.stl"/>
      </geometry>
    </collision>
    <!-- Part wrist_roll_follower_so101_v1 -->
    <visual>
      <origin xyz="5.55112e-17 -0.000218214 0.000949706" rpy="3.14159 -5.55112e-17 -2.54515e-32"/>
      <geometry>
        <mesh filename="meshes/wrist_roll_follower_so101_v1.stl"/>
      </geometry>
      <material name="3d_printed"/>
    </visual>
    <collision>
      <origin xyz="5.55112e-17 -0.000218214 0.000949706" rpy="3.14159 -5.55112e-17 -2.54515e-32"/>
      <geometry>
        <mesh filename="meshes/wrist_roll_follower_so101_v1.stl"/>
      </geometry>
    </collision>
  </link>

  <!-- Moving_Jaw Link -->
  <link name="Moving_Jaw">
    <inertial>
      <origin xyz="-0.00157495 -0.0300244 0.0192755" rpy="0 0 0"/>
      <mass value="0.012"/>
      <inertia ixx="6.61427e-06" ixy="-3.19807e-07" ixz="-5.90717e-09" iyy="1.89032e-06" iyz="-1.09945e-07" izz="5.28738e-06"/>
    </inertial>
    <!-- Part moving_jaw_so101_v1 -->
    <visual>
      <origin xyz="2.77556e-17 -1.31397e-17 0.0189" rpy="9.53145e-17 1.02153e-32 1.57772e-30"/>
      <geometry>
        <mesh filename="meshes/moving_jaw_so101_v1.stl"/>
      </geometry>
      <material name="3d_printed"/>
    </visual>
    <collision>
      <origin xyz="2.77556e-17 -1.31397e-17 0.0189" rpy="9.53145e-17 1.02153e-32 1.57772e-30"/>
      <geometry>
        <mesh filename="meshes/moving_jaw_so101_v1.stl"/>
      </geometry>
    </collision>
  </link>

  <!-- Joint from Base to Rotation_Pitch -->
  <joint name="Rotation" type="revolute">
    <origin xyz="0.0207909 -0.0230745 0.0948817" rpy="-3.14159 6.03684e-16 1.5708"/>
    <parent link="Base"/>
    <child link="Rotation_Pitch"/>
    <axis xyz="0 0 1"/>
    <limit effort="10" velocity="10" lower="-1.91986" upper="1.91986"/>
  </joint>

  <transmission name="Rotation_trans">
    <type>transmission_interface/SimpleTransmission</type>
    <joint name="Rotation">
      <hardwareInterface>hardware_interface/PositionJointInterface</hardwareInterface>
    </joint>
    <actuator name="Rotation_motor">
      <hardwareInterface>hardware_interface/PositionJointInterface</hardwareInterface>
      <mechanicalReduction>1</mechanicalReduction>
    </actuator>
  </transmission>

  <!-- Joint from Rotation_Pitch to Upper_Arm -->
  <joint name="Pitch" type="revolute">
    <origin xyz="-0.0303992 -0.0182778 -0.0542" rpy="1.5708 8.18789e-16 3.14159"/>
    <parent link="Rotation_Pitch"/>
    <child link="Upper_Arm"/>
    <axis xyz="0 0 1"/>
    <limit effort="10" velocity="10" lower="-0.174533" upper="3.31613"/>
  </joint>

  <transmission name="Pitch_trans">
    <type>transmission_interface/SimpleTransmission</type>
    <joint name="Pitch">
      <hardwareInterface>hardware_interface/PositionJointInterface</hardwareInterface>
    </joint>
    <actuator name="Pitch_motor">
      <hardwareInterface>hardware_interface/PositionJointInterface</hardwareInterface>
      <mechanicalReduction>1</mechanicalReduction>
    </actuator>
  </transmission>

  <!-- Joint from Upper Arm to Lower Arm -->
  <joint name="Elbow" type="revolute">
    <origin xyz="-0.11257 -0.028 2.29417e-16" rpy="-2.26208e-15 -1.3739e-15 3.14159"/>
    <parent link="Upper_Arm"/>
    <child link="Lower_Arm"/>
    <axis xyz="0 0 1"/>
    <limit effort="10" velocity="10" lower="-3.22886" upper="0.0872665"/>
  </joint>

  <transmission name="Elbow_trans">
    <type>transmission_interface/SimpleTransmission</type>
    <joint name="Elbow">
      <hardwareInterface>hardware_interface/PositionJointInterface</hardwareInterface>
    </joint>
    <actuator name="Elbow_motor">
      <hardwareInterface>hardware_interface/PositionJointInterface</hardwareInterface>
      <mechanicalReduction>1</mechanicalReduction>
    </actuator>
  </transmission>

  <!-- Joint from Lower_Arm to Wrist_Pitch_Roll -->
  <joint name="Wrist_Pitch" type="revolute">
    <origin xyz="-0.1349 0.0052 3.21791e-16" rpy="-1.11022e-16 1.11022e-16 -1.5708"/>
    <parent link="Lower_Arm"/>
    <child link="Wrist_Pitch_Roll"/>
    <axis xyz="0 0 1"/>
    <limit effort="10" velocity="10" lower="-1.65806" upper="1.65806"/>
  </joint>

  <transmission name="Wrist_Pitch_trans">
    <type>transmission_interface/SimpleTransmission</type>
    <joint name="Wrist_Pitch">
      <hardwareInterface>hardware_interface/PositionJointInterface</hardwareInterface>
    </joint>
    <actuator name="Wrist_Pitch_motor">
      <hardwareInterface>hardware_interface/PositionJointInterface</hardwareInterface>
      <mechanicalReduction>1</mechanicalReduction>
    </actuator>
  </transmission>

  <!-- Joint from Wrist_Pitch_Roll to Fixed_Jaw -->
  <joint name="Wrist_Roll" type="revolute">
    <origin xyz="-2.77556e-17 -0.0611 0.0181" rpy="1.5708 2.18394e-16 3.14159"/>
    <parent link="Wrist_Pitch_Roll"/>
    <child link="Fixed_Jaw"/>
    <axis xyz="0 0 1"/>
    <limit effort="10" velocity="10" lower="-2.79253" upper="2.79253"/>
  </joint>

  <transmission name="Wrist_Roll_trans">
    <type>transmission_interface/SimpleTransmission</type>
    <joint name="Wrist_Roll">
      <hardwareInterface>hardware_interface/PositionJointInterface</hardwareInterface>
    </joint>
    <actuator name="Wrist_Roll_motor">
      <hardwareInterface>hardware_interface/PositionJointInterface</hardwareInterface>
      <mechanicalReduction>1</mechanicalReduction>
    </actuator>
  </transmission>

  <!-- Joint from Fixed_Jaw to Moving_Jaw -->
  <joint name="Jaw" type="revolute">
    <origin xyz="0.0202 0.0188 -0.0234" rpy="1.5708 4.00612e-15 -2.2678e-16"/>
    <parent link="Fixed_Jaw"/>
    <child link="Moving_Jaw"/>
    <axis xyz="0 0 1"/>
    <limit effort="10" velocity="10" lower="-0.261799" upper="1.74533"/>
  </joint>

  <transmission name="Jaw_trans">
    <type>transmission_interface/SimpleTransmission</type>
    <joint name="Jaw">
      <hardwareInterface>hardware_interface/PositionJointInterface</hardwareInterface>
    </joint>
    <actuator name="Jaw_motor">
      <hardwareInterface>hardware_interface/PositionJointInterface</hardwareInterface>
      <mechanicalReduction>1</mechanicalReduction>
    </actuator>
  </transmission>

</robot>